GPUassert: invalid argument ./src/GPU/dynamic-edge-update.cu 739
Traceback (most recent call last):
  File "run.py", line 102, in <module>
    run(exec_map[(algo,gpuflag)]+ " ./datasets/{}.in ./queries/edge-update-queries/queries_{}/{}_queries ./output/{} {}".format(dataset, batch, dataset, outfile, numthread), shell=True, check=True)
  File "/usr/lib64/python3.6/subprocess.py", line 438, in run
    output=stdout, stderr=stderr)
subprocess.CalledProcessError: Command './exec/GPU/deu ./datasets/brightkite.in ./queries/edge-update-queries/queries_10/brightkite_queries ./output/p64_q10_gpu_dynedge_brightkite.txt ['32']' returned non-zero exit status 1.
GPUassert: invalid argument ./src/GPU/dynamic-edge-update.cu 739
Traceback (most recent call last):
  File "run.py", line 102, in <module>
    run(exec_map[(algo,gpuflag)]+ " ./datasets/{}.in ./queries/edge-update-queries/queries_{}/{}_queries ./output/{} {}".format(dataset, batch, dataset, outfile, numthread), shell=True, check=True)
  File "/usr/lib64/python3.6/subprocess.py", line 438, in run
    output=stdout, stderr=stderr)
subprocess.CalledProcessError: Command './exec/GPU/deu ./datasets/brightkite.in ./queries/edge-update-queries/queries_100/brightkite_queries ./output/p64_q100_gpu_dynedge_brightkite.txt ['32']' returned non-zero exit status 1.
GPUassert: invalid argument ./src/GPU/dynamic-edge-update.cu 739
Traceback (most recent call last):
  File "run.py", line 102, in <module>
    run(exec_map[(algo,gpuflag)]+ " ./datasets/{}.in ./queries/edge-update-queries/queries_{}/{}_queries ./output/{} {}".format(dataset, batch, dataset, outfile, numthread), shell=True, check=True)
  File "/usr/lib64/python3.6/subprocess.py", line 438, in run
    output=stdout, stderr=stderr)
subprocess.CalledProcessError: Command './exec/GPU/deu ./datasets/brightkite.in ./queries/edge-update-queries/queries_1000/brightkite_queries ./output/p64_q1000_gpu_dynedge_brightkite.txt ['32']' returned non-zero exit status 1.
GPUassert: invalid argument ./src/GPU/dynamic-edge-update.cu 739
Traceback (most recent call last):
  File "run.py", line 102, in <module>
    run(exec_map[(algo,gpuflag)]+ " ./datasets/{}.in ./queries/edge-update-queries/queries_{}/{}_queries ./output/{} {}".format(dataset, batch, dataset, outfile, numthread), shell=True, check=True)
  File "/usr/lib64/python3.6/subprocess.py", line 438, in run
    output=stdout, stderr=stderr)
subprocess.CalledProcessError: Command './exec/GPU/deu ./datasets/brightkite.in ./queries/edge-update-queries/queries_5000/brightkite_queries ./output/p64_q5000_gpu_dynedge_brightkite.txt ['32']' returned non-zero exit status 1.
GPUassert: invalid argument ./src/GPU/dynamic-edge-update.cu 739
Traceback (most recent call last):
  File "run.py", line 102, in <module>
    run(exec_map[(algo,gpuflag)]+ " ./datasets/{}.in ./queries/edge-update-queries/queries_{}/{}_queries ./output/{} {}".format(dataset, batch, dataset, outfile, numthread), shell=True, check=True)
  File "/usr/lib64/python3.6/subprocess.py", line 438, in run
    output=stdout, stderr=stderr)
subprocess.CalledProcessError: Command './exec/GPU/deu ./datasets/brightkite.in ./queries/edge-update-queries/queries_100000/brightkite_queries ./output/p64_q100000_gpu_dynedge_brightkite.txt ['32']' returned non-zero exit status 1.
