./datasets/email-enron.in,28777326,10,28662,89,107,15,1004878,4,220,999429,2033439
./datasets/email-enron.in,28898130,100,30474,85,106,18,1004876,25,232,1005319,2041171
./datasets/email-enron.in,28873468,1000,63417,93,107,16,1004935,165,224,1018798,2087790
./datasets/email-enron.in,28860812,5000,178851,100,107,16,1008541,624,205,1066770,2255253
./datasets/email-enron.in,GPUassert: no CUDA-capable device is detected ./src/GPU/dynamic-edge-update.cu 742
Traceback (most recent call last):
  File "/DATA/prajjwal/dynamic-percolation-centrality/run.py", line 114, in <module>
    run(exec_map[(algo,gpuflag)]+ " ./datasets/{}.in ./queries/edge-update-queries/queries_{}/{}_queries ./output/{} {}".format(dataset, batch, dataset, outfile, numthread), shell=True, check=True)
  File "/usr/lib/python3.10/subprocess.py", line 526, in run
    raise CalledProcessError(retcode, process.args,
subprocess.CalledProcessError: Command 'CUDA_VISIBLE_DEVICES=2 ./exec/GPU/deu ./datasets/email-enron.in ./queries/edge-update-queries/queries_10/email-enron_queries ./output/p64_q10_gpu_dynedge_email-enron.txt ['32']' returned non-zero exit status 100.
./datasets/email-enron.in,GPUassert: no CUDA-capable device is detected ./src/GPU/dynamic-edge-update.cu 742
Traceback (most recent call last):
  File "/DATA/prajjwal/dynamic-percolation-centrality/run.py", line 114, in <module>
    run(exec_map[(algo,gpuflag)]+ " ./datasets/{}.in ./queries/edge-update-queries/queries_{}/{}_queries ./output/{} {}".format(dataset, batch, dataset, outfile, numthread), shell=True, check=True)
  File "/usr/lib/python3.10/subprocess.py", line 526, in run
    raise CalledProcessError(retcode, process.args,
subprocess.CalledProcessError: Command 'CUDA_VISIBLE_DEVICES=2 ./exec/GPU/deu ./datasets/email-enron.in ./queries/edge-update-queries/queries_100/email-enron_queries ./output/p64_q100_gpu_dynedge_email-enron.txt ['32']' returned non-zero exit status 100.
./datasets/email-enron.in,GPUassert: no CUDA-capable device is detected ./src/GPU/dynamic-edge-update.cu 742
Traceback (most recent call last):
  File "/DATA/prajjwal/dynamic-percolation-centrality/run.py", line 114, in <module>
    run(exec_map[(algo,gpuflag)]+ " ./datasets/{}.in ./queries/edge-update-queries/queries_{}/{}_queries ./output/{} {}".format(dataset, batch, dataset, outfile, numthread), shell=True, check=True)
  File "/usr/lib/python3.10/subprocess.py", line 526, in run
    raise CalledProcessError(retcode, process.args,
subprocess.CalledProcessError: Command 'CUDA_VISIBLE_DEVICES=2 ./exec/GPU/deu ./datasets/email-enron.in ./queries/edge-update-queries/queries_1000/email-enron_queries ./output/p64_q1000_gpu_dynedge_email-enron.txt ['32']' returned non-zero exit status 100.
./datasets/email-enron.in,GPUassert: no CUDA-capable device is detected ./src/GPU/dynamic-edge-update.cu 742
Traceback (most recent call last):
  File "/DATA/prajjwal/dynamic-percolation-centrality/run.py", line 114, in <module>
    run(exec_map[(algo,gpuflag)]+ " ./datasets/{}.in ./queries/edge-update-queries/queries_{}/{}_queries ./output/{} {}".format(dataset, batch, dataset, outfile, numthread), shell=True, check=True)
  File "/usr/lib/python3.10/subprocess.py", line 526, in run
    raise CalledProcessError(retcode, process.args,
subprocess.CalledProcessError: Command 'CUDA_VISIBLE_DEVICES=2 ./exec/GPU/deu ./datasets/email-enron.in ./queries/edge-update-queries/queries_5000/email-enron_queries ./output/p64_q5000_gpu_dynedge_email-enron.txt ['32']' returned non-zero exit status 100.
