14663893,2326458
14645195,2327770
14624869,2365831
14637128,GPUassert: an illegal memory access was encountered ./src/GPU/dynamic-edge-update.cu 810
Traceback (most recent call last):
  File "run.py", line 102, in <module>
    run(exec_map[(algo,gpuflag)]+ " ./datasets/{}.in ./queries/edge-update-queries/queries_{}/{}_queries ./output/{} {}".format(dataset, batch, dataset, outfile, numthread), shell=True, check=True)
  File "/usr/lib64/python3.6/subprocess.py", line 438, in run
    output=stdout, stderr=stderr)
subprocess.CalledProcessError: Command './exec/GPU/deu ./datasets/p2p-Gnutella25.in ./queries/edge-update-queries/queries_5000/p2p-Gnutella25_queries ./output/p64_q5000_gpu_dynedge_p2p-Gnutella25.txt ['32']' returned non-zero exit status 188.
14638975,GPUassert: an illegal memory access was encountered ./src/GPU/dynamic-edge-update.cu 810
Traceback (most recent call last):
  File "run.py", line 102, in <module>
    run(exec_map[(algo,gpuflag)]+ " ./datasets/{}.in ./queries/edge-update-queries/queries_{}/{}_queries ./output/{} {}".format(dataset, batch, dataset, outfile, numthread), shell=True, check=True)
  File "/usr/lib64/python3.6/subprocess.py", line 438, in run
    output=stdout, stderr=stderr)
subprocess.CalledProcessError: Command './exec/GPU/deu ./datasets/p2p-Gnutella25.in ./queries/edge-update-queries/queries_100000/p2p-Gnutella25_queries ./output/p64_q100000_gpu_dynedge_p2p-Gnutella25.txt ['32']' returned non-zero exit status 188.
