./datasets/p2p-Gnutella30.in,47840696,10,29764,92,165,16,990934,4,162,991408,2012581
./datasets/p2p-Gnutella30.in,48141626,100,32995,89,165,16,992547,27,1691,992383,2019950
./datasets/p2p-Gnutella30.in,48135676,1000,72451,112,169,17,990887,168,158,998070,2062069
./datasets/p2p-Gnutella30.in,48033922,5000,183409,94,164,15,990613,655,156,1027736,2202884
./datasets/p2p-Gnutella30.in,GPUassert: no CUDA-capable device is detected ./src/GPU/dynamic-edge-update.cu 742
Traceback (most recent call last):
  File "/DATA/prajjwal/dynamic-percolation-centrality/run.py", line 114, in <module>
    run(exec_map[(algo,gpuflag)]+ " ./datasets/{}.in ./queries/edge-update-queries/queries_{}/{}_queries ./output/{} {}".format(dataset, batch, dataset, outfile, numthread), shell=True, check=True)
  File "/usr/lib/python3.10/subprocess.py", line 526, in run
    raise CalledProcessError(retcode, process.args,
subprocess.CalledProcessError: Command 'CUDA_VISIBLE_DEVICES=2 ./exec/GPU/deu ./datasets/p2p-Gnutella30.in ./queries/edge-update-queries/queries_10/p2p-Gnutella30_queries ./output/p64_q10_gpu_dynedge_p2p-Gnutella30.txt ['32']' returned non-zero exit status 100.
./datasets/p2p-Gnutella30.in,GPUassert: no CUDA-capable device is detected ./src/GPU/dynamic-edge-update.cu 742
Traceback (most recent call last):
  File "/DATA/prajjwal/dynamic-percolation-centrality/run.py", line 114, in <module>
    run(exec_map[(algo,gpuflag)]+ " ./datasets/{}.in ./queries/edge-update-queries/queries_{}/{}_queries ./output/{} {}".format(dataset, batch, dataset, outfile, numthread), shell=True, check=True)
  File "/usr/lib/python3.10/subprocess.py", line 526, in run
    raise CalledProcessError(retcode, process.args,
subprocess.CalledProcessError: Command 'CUDA_VISIBLE_DEVICES=2 ./exec/GPU/deu ./datasets/p2p-Gnutella30.in ./queries/edge-update-queries/queries_100/p2p-Gnutella30_queries ./output/p64_q100_gpu_dynedge_p2p-Gnutella30.txt ['32']' returned non-zero exit status 100.
./datasets/p2p-Gnutella30.in,GPUassert: no CUDA-capable device is detected ./src/GPU/dynamic-edge-update.cu 742
Traceback (most recent call last):
  File "/DATA/prajjwal/dynamic-percolation-centrality/run.py", line 114, in <module>
    run(exec_map[(algo,gpuflag)]+ " ./datasets/{}.in ./queries/edge-update-queries/queries_{}/{}_queries ./output/{} {}".format(dataset, batch, dataset, outfile, numthread), shell=True, check=True)
  File "/usr/lib/python3.10/subprocess.py", line 526, in run
    raise CalledProcessError(retcode, process.args,
subprocess.CalledProcessError: Command 'CUDA_VISIBLE_DEVICES=2 ./exec/GPU/deu ./datasets/p2p-Gnutella30.in ./queries/edge-update-queries/queries_1000/p2p-Gnutella30_queries ./output/p64_q1000_gpu_dynedge_p2p-Gnutella30.txt ['32']' returned non-zero exit status 100.
./datasets/p2p-Gnutella30.in,GPUassert: no CUDA-capable device is detected ./src/GPU/dynamic-edge-update.cu 742
Traceback (most recent call last):
  File "/DATA/prajjwal/dynamic-percolation-centrality/run.py", line 114, in <module>
    run(exec_map[(algo,gpuflag)]+ " ./datasets/{}.in ./queries/edge-update-queries/queries_{}/{}_queries ./output/{} {}".format(dataset, batch, dataset, outfile, numthread), shell=True, check=True)
  File "/usr/lib/python3.10/subprocess.py", line 526, in run
    raise CalledProcessError(retcode, process.args,
subprocess.CalledProcessError: Command 'CUDA_VISIBLE_DEVICES=2 ./exec/GPU/deu ./datasets/p2p-Gnutella30.in ./queries/edge-update-queries/queries_5000/p2p-Gnutella30_queries ./output/p64_q5000_gpu_dynedge_p2p-Gnutella30.txt ['32']' returned non-zero exit status 100.
