./datasets/PGPgiantcompo.in,485887,10,267960
./datasets/PGPgiantcompo.in,492574,100,268906
./datasets/PGPgiantcompo.in,465937,1000,277170
./datasets/PGPgiantcompo.in,501086,5000,294391
./datasets/PGPgiantcompo.in,GPUassert: no CUDA-capable device is detected ./src/GPU/static-edge-update.cu 259
Traceback (most recent call last):
  File "/DATA/prajjwal/dynamic-percolation-centrality/run.py", line 114, in <module>
    run(exec_map[(algo,gpuflag)]+ " ./datasets/{}.in ./queries/edge-update-queries/queries_{}/{}_queries ./output/{} {}".format(dataset, batch, dataset, outfile, numthread), shell=True, check=True)
  File "/usr/lib/python3.10/subprocess.py", line 526, in run
    raise CalledProcessError(retcode, process.args,
subprocess.CalledProcessError: Command 'CUDA_VISIBLE_DEVICES=2 ./exec/GPU/seu ./datasets/PGPgiantcompo.in ./queries/edge-update-queries/queries_10/PGPgiantcompo_queries ./output/p64_q10_gpu_statedge_PGPgiantcompo.txt ['32']' returned non-zero exit status 100.
./datasets/PGPgiantcompo.in,GPUassert: no CUDA-capable device is detected ./src/GPU/static-edge-update.cu 259
Traceback (most recent call last):
  File "/DATA/prajjwal/dynamic-percolation-centrality/run.py", line 114, in <module>
    run(exec_map[(algo,gpuflag)]+ " ./datasets/{}.in ./queries/edge-update-queries/queries_{}/{}_queries ./output/{} {}".format(dataset, batch, dataset, outfile, numthread), shell=True, check=True)
  File "/usr/lib/python3.10/subprocess.py", line 526, in run
    raise CalledProcessError(retcode, process.args,
subprocess.CalledProcessError: Command 'CUDA_VISIBLE_DEVICES=2 ./exec/GPU/seu ./datasets/PGPgiantcompo.in ./queries/edge-update-queries/queries_100/PGPgiantcompo_queries ./output/p64_q100_gpu_statedge_PGPgiantcompo.txt ['32']' returned non-zero exit status 100.
./datasets/PGPgiantcompo.in,GPUassert: no CUDA-capable device is detected ./src/GPU/static-edge-update.cu 259
Traceback (most recent call last):
  File "/DATA/prajjwal/dynamic-percolation-centrality/run.py", line 114, in <module>
    run(exec_map[(algo,gpuflag)]+ " ./datasets/{}.in ./queries/edge-update-queries/queries_{}/{}_queries ./output/{} {}".format(dataset, batch, dataset, outfile, numthread), shell=True, check=True)
  File "/usr/lib/python3.10/subprocess.py", line 526, in run
    raise CalledProcessError(retcode, process.args,
subprocess.CalledProcessError: Command 'CUDA_VISIBLE_DEVICES=2 ./exec/GPU/seu ./datasets/PGPgiantcompo.in ./queries/edge-update-queries/queries_1000/PGPgiantcompo_queries ./output/p64_q1000_gpu_statedge_PGPgiantcompo.txt ['32']' returned non-zero exit status 100.
./datasets/PGPgiantcompo.in,GPUassert: no CUDA-capable device is detected ./src/GPU/static-edge-update.cu 259
Traceback (most recent call last):
  File "/DATA/prajjwal/dynamic-percolation-centrality/run.py", line 114, in <module>
    run(exec_map[(algo,gpuflag)]+ " ./datasets/{}.in ./queries/edge-update-queries/queries_{}/{}_queries ./output/{} {}".format(dataset, batch, dataset, outfile, numthread), shell=True, check=True)
  File "/usr/lib/python3.10/subprocess.py", line 526, in run
    raise CalledProcessError(retcode, process.args,
subprocess.CalledProcessError: Command 'CUDA_VISIBLE_DEVICES=2 ./exec/GPU/seu ./datasets/PGPgiantcompo.in ./queries/edge-update-queries/queries_5000/PGPgiantcompo_queries ./output/p64_q5000_gpu_statedge_PGPgiantcompo.txt ['32']' returned non-zero exit status 100.
