4921857,108165
4913897,117563
4927578,116520
4901212,132121
4917828,GPUassert: an illegal memory access was encountered ./src/GPU/dynamic-edge-update.cu 810
Traceback (most recent call last):
  File "run.py", line 102, in <module>
    run(exec_map[(algo,gpuflag)]+ " ./datasets/{}.in ./queries/edge-update-queries/queries_{}/{}_queries ./output/{} {}".format(dataset, batch, dataset, outfile, numthread), shell=True, check=True)
  File "/usr/lib/python3.8/subprocess.py", line 516, in run
    raise CalledProcessError(retcode, process.args,
subprocess.CalledProcessError: Command './exec/GPU/deu ./datasets/PGPgiantcompo.in ./queries/edge-update-queries/queries_100000/PGPgiantcompo_queries ./output/p64_q100000_gpu_dynedge_PGPgiantcompo.txt ['32']' returned non-zero exit status 188.
