./datasets/slashdot.in,6546683,10,6300763
./datasets/slashdot.in,6527723,100,6302178
./datasets/slashdot.in,6555687,1000,6318348
./datasets/slashdot.in,6507619,5000,6421548
./datasets/slashdot.in,GPUassert: no CUDA-capable device is detected ./src/GPU/static-edge-update.cu 259
Traceback (most recent call last):
  File "/DATA/prajjwal/dynamic-percolation-centrality/run.py", line 114, in <module>
    run(exec_map[(algo,gpuflag)]+ " ./datasets/{}.in ./queries/edge-update-queries/queries_{}/{}_queries ./output/{} {}".format(dataset, batch, dataset, outfile, numthread), shell=True, check=True)
  File "/usr/lib/python3.10/subprocess.py", line 526, in run
    raise CalledProcessError(retcode, process.args,
subprocess.CalledProcessError: Command 'CUDA_VISIBLE_DEVICES=2 ./exec/GPU/seu ./datasets/slashdot.in ./queries/edge-update-queries/queries_10/slashdot_queries ./output/p64_q10_gpu_statedge_slashdot.txt ['32']' returned non-zero exit status 100.
./datasets/slashdot.in,GPUassert: no CUDA-capable device is detected ./src/GPU/static-edge-update.cu 259
Traceback (most recent call last):
  File "/DATA/prajjwal/dynamic-percolation-centrality/run.py", line 114, in <module>
    run(exec_map[(algo,gpuflag)]+ " ./datasets/{}.in ./queries/edge-update-queries/queries_{}/{}_queries ./output/{} {}".format(dataset, batch, dataset, outfile, numthread), shell=True, check=True)
  File "/usr/lib/python3.10/subprocess.py", line 526, in run
    raise CalledProcessError(retcode, process.args,
subprocess.CalledProcessError: Command 'CUDA_VISIBLE_DEVICES=2 ./exec/GPU/seu ./datasets/slashdot.in ./queries/edge-update-queries/queries_100/slashdot_queries ./output/p64_q100_gpu_statedge_slashdot.txt ['32']' returned non-zero exit status 100.
./datasets/slashdot.in,GPUassert: no CUDA-capable device is detected ./src/GPU/static-edge-update.cu 259
Traceback (most recent call last):
  File "/DATA/prajjwal/dynamic-percolation-centrality/run.py", line 114, in <module>
    run(exec_map[(algo,gpuflag)]+ " ./datasets/{}.in ./queries/edge-update-queries/queries_{}/{}_queries ./output/{} {}".format(dataset, batch, dataset, outfile, numthread), shell=True, check=True)
  File "/usr/lib/python3.10/subprocess.py", line 526, in run
    raise CalledProcessError(retcode, process.args,
subprocess.CalledProcessError: Command 'CUDA_VISIBLE_DEVICES=2 ./exec/GPU/seu ./datasets/slashdot.in ./queries/edge-update-queries/queries_1000/slashdot_queries ./output/p64_q1000_gpu_statedge_slashdot.txt ['32']' returned non-zero exit status 100.
./datasets/slashdot.in,GPUassert: no CUDA-capable device is detected ./src/GPU/static-edge-update.cu 259
Traceback (most recent call last):
  File "/DATA/prajjwal/dynamic-percolation-centrality/run.py", line 114, in <module>
    run(exec_map[(algo,gpuflag)]+ " ./datasets/{}.in ./queries/edge-update-queries/queries_{}/{}_queries ./output/{} {}".format(dataset, batch, dataset, outfile, numthread), shell=True, check=True)
  File "/usr/lib/python3.10/subprocess.py", line 526, in run
    raise CalledProcessError(retcode, process.args,
subprocess.CalledProcessError: Command 'CUDA_VISIBLE_DEVICES=2 ./exec/GPU/seu ./datasets/slashdot.in ./queries/edge-update-queries/queries_5000/slashdot_queries ./output/p64_q5000_gpu_statedge_slashdot.txt ['32']' returned non-zero exit status 100.
